======================================================
=== RUNNING FINAL VERSION: V4 - HARDCODED TOKEN ===
=== SCRIPT DEPLOYED AT: 2025-06-21 22:57:30.985291-04:00 ===
======================================================
Initializing core systems...
[InteractiveBot] Initializing...
[InteractiveBot] Initialization complete.
Shutting down all active symbol monitors...
Traceback (most recent call last):
  File "C:\Users\Reza\Desktop\gitload\SignalBot\main.py", line 201, in main
    await asyncio.gather(
    ...<2 lines>...
    )
  File "C:\Users\Reza\Desktop\gitload\SignalBot\main.py", line 148, in daily_reset_task
    perform_daily_reinitialization(app_config['symbols'], state_manager, position_manager)
    ~~~~~~~~~~~~~~~~~~~~~~~~~~~~~~^^^^^^^^^^^^^^^^^^^^^^^^^^^^^^^^^^^^^^^^^^^^^^^^^^^^^^^^
  File "C:\Users\Reza\Desktop\gitload\SignalBot\main.py", line 109, in perform_daily_reinitialization
    print(f"\n===== \U0001f5fd STARTING NY-BASED DAILY INITIALIZATION FOR {analysis_end_time_ny.date()} \U0001f5fd =====")
    ~~~~~^^^^^^^^^^^^^^^^^^^^^^^^^^^^^^^^^^^^^^^^^^^^^^^^^^^^^^^^^^^^^^^^^^^^^^^^^^^^^^^^^^^^^^^^^^^^^^^^^
  File "C:\Python313\Lib\encodings\cp1252.py", line 19, in encode
    return codecs.charmap_encode(input,self.errors,encoding_table)[0]
           ~~~~~~~~~~~~~~~~~~~~~^^^^^^^^^^^^^^^^^^^^^^^^^^^^^^^^^^
UnicodeEncodeError: 'charmap' codec can't encode character '\U0001f5fd' in position 8: character maps to <undefined>

During handling of the above exception, another exception occurred:

Traceback (most recent call last):
  File "C:\Users\Reza\Desktop\gitload\SignalBot\main.py", line 212, in <module>
    asyncio.run(main())
    ~~~~~~~~~~~^^^^^^^^
  File "C:\Python313\Lib\asyncio\runners.py", line 195, in run
    return runner.run(main)
           ~~~~~~~~~~^^^^^^
  File "C:\Python313\Lib\asyncio\runners.py", line 118, in run
    return self._loop.run_until_complete(task)
           ~~~~~~~~~~~~~~~~~~~~~~~~~~~~~^^^^^^
  File "C:\Python313\Lib\asyncio\base_events.py", line 719, in run_until_complete
    return future.result()
           ~~~~~~~~~~~~~^^
  File "C:\Users\Reza\Desktop\gitload\SignalBot\main.py", line 196, in main
    async with interactive_bot.application:
               ^^^^^^^^^^^^^^^^^^^^^^^^^^^
  File "C:\Users\Reza\AppData\Roaming\Python\Python313\site-packages\telegram\ext\_application.py", line 384, in __aexit__
    await self.shutdown()
  File "C:\Users\Reza\AppData\Roaming\Python\Python313\site-packages\telegram\ext\_application.py", line 534, in shutdown
    raise RuntimeError("This Application is still running!")
RuntimeError: This Application is still running!
